<?xml version="1.0"?>
<!-- created with Phobos 0.7 -->
<sdf version="1.5">
  <model name="deepleng_docking_station">
    <link name="docking_station">
      <pose>0 0 0 0 0 0</pose>
      <collision name="collision_tube_top">
        <pose>-0.34668 0 0.99545 0 0 0</pose>
        <geometry>
          <cylinder>
            <radius>0.14</radius>
            <length>2.20122</length>
          </cylinder>
        </geometry>
      </collision>
      <collision name="collision_guiding_rail_right">
        <pose>0 0 0 -3.14159 0 0</pose>
        <geometry>
          <mesh>
            <uri>model://deepleng_docking_station/meshes/small_guiding_rail.dae</uri>
          </mesh>
        </geometry>
      </collision>
      <collision name="collision_guiding_rail_top_left">
        <pose>0 0 0 -1.0472 0 0</pose>
        <geometry>
          <mesh>
            <uri>model://deepleng_docking_station/meshes/big_guiding_rail.dae</uri>
          </mesh>
        </geometry>
      </collision>
      <collision name="collision_guiding_rail_top_right">
        <pose>0 0 0 -2.0944 0 0</pose>
        <geometry>
          <mesh>
            <uri>model://deepleng_docking_station/meshes/big_guiding_rail.dae</uri>
          </mesh>
        </geometry>
      </collision>
      <collision name="collision_guiding_rail_bottom_right">
        <pose>0 0 0 2.0944 0 0</pose>
        <geometry>
          <mesh>
            <uri>model://deepleng_docking_station/meshes/big_guiding_rail.dae</uri>
          </mesh>
        </geometry>
      </collision>
      <collision name="collision_tube_bottom">
        <pose>-0.27205 0 0.00186 0 1.5708 0</pose>
        <geometry>
          <cylinder>
            <radius>0.14</radius>
            <length>0.4254</length>
          </cylinder>
        </geometry>
      </collision>
      <collision name="collision_guiding_rail_bottom_left">
        <pose>0 0 0 1.0472 0 0</pose>
        <geometry>
          <mesh>
            <uri>model://deepleng_docking_station/meshes/big_guiding_rail.dae</uri>
          </mesh>
        </geometry>
      </collision>
      <collision name="collision_guiding_rail_left">
        <pose>0 0 0 0 0 0</pose>
        <geometry>
          <mesh>
            <uri>model://deepleng_docking_station/meshes/small_guiding_rail.dae</uri>
          </mesh>
        </geometry>
      </collision>
      <visual name="visual_tube">
        <pose>0 0 0 0 0 0</pose>
        <geometry>
          <mesh>
            <uri>model://deepleng_docking_station/meshes/tube.dae</uri>
          </mesh>
        </geometry>
      </visual>
    </link>
    <link name="actuator_gripper_left">
      <pose>-0.09211 -0.10933 0.00159 0 0 -0.17453</pose>
      <collision name="collision_gripper_left">
        <pose>0 0 0 0 0 0</pose>
        <geometry>
          <mesh>
            <uri>model://deepleng_docking_station/meshes/gripper.dae</uri>
          </mesh>
        </geometry>
      </collision>
      <visual name="visual_gripper_left">
        <pose>0 0 0 0 0 0</pose>
        <geometry>
          <mesh>
            <uri>model://deepleng_docking_station/meshes/gripper.dae</uri>
          </mesh>
        </geometry>
      </visual>
    </link>
    <link name="actuator_gripper_right">
      <pose>-0.09211 0.10927 0.00159 0 0 0.17453</pose>
      <collision name="collision_gripper_right">
        <pose>0 0 0 -3.14159 0 0</pose>
        <geometry>
          <mesh>
            <uri>model://deepleng_docking_station/meshes/gripper.dae</uri>
          </mesh>
        </geometry>
      </collision>
      <visual name="visual_gripper_right">
        <pose>0 0 0 -3.141592264175415 -0.0 0.0</pose>
        <geometry>
          <mesh>
            <uri>model://deepleng_docking_station/meshes/gripper.dae</uri>
            <scale>1.0 1.0 1.0</scale>
          </mesh>
        </geometry>
      </visual>
    </link>
    <joint type="revolute" name="actuator_gripper_left">
      <parent>docking_station</parent>
      <child>actuator_gripper_left</child>
      <pose>0 0 0 0 0 0</pose>
      <axis>
        <xyz>0 0 1.0</xyz>
        <limit>
          <lower>-40.0</lower>
          <upper>40.0</upper>
          <effort>100.0</effort>
          <velocity>0.5</velocity>
        </limit>
      </axis>
    </joint>
    <joint type="revolute" name="actuator_gripper_right">
      <parent>docking_station</parent>
      <child>actuator_gripper_right</child>
      <pose>0 0 0 0 0 0</pose>
      <axis>
        <xyz>0 0 1.0</xyz>
        <limit>
          <lower>-3.0</lower>
          <upper>3.0</upper>
          <effort>100.0</effort>
          <velocity>0.5</velocity>
        </limit>
      </axis>
    </joint>
  </model>
</sdf>
